{"uuid": "62996cd8-552b-4f3a-bf26-e3fa940bc787", "children": ["7bf8ebf8-a9bd-4a85-9331-04ea817b15f0", "fe393b65-c94b-4e02-a6a6-d007e8025322", "86178c23-00f1-4361-80b8-8c48dc95eea2", "f2fc84c0-611c-49a7-badf-5de2539b40a0", "aa259d3b-e0cb-4c11-8e73-74e8a070dcaa", "307a8f48-3482-4a4c-b3f5-2a7d43ae73e2", "de34a3b0-c484-4ec5-8a1b-7e69c4a32b4b", "36dfc8ff-20b7-4708-b8b4-99ae03749aef", "1553d846-d646-4f08-9900-ecf30eade71b", "3be28753-d47e-4685-a29c-7e9c21420da2", "d5899954-2bd3-41d9-8b12-faade650f256", "50cc3f8a-ea87-4a43-a387-0c81d9ca8201"], "befores": [{"name": "driver_get", "status": "passed", "start": 1603353626355, "stop": 1603353630163}], "afters": [{"name": "driver_get::0", "status": "broken", "statusDetails": {"message": "selenium.common.exceptions.WebDriverException: Message: chrome not reachable\n  (Session info: chrome=86.0.4240.75)\n\n", "trace": "  File \"c:\\basicpythonautomationframework\\venv\\lib\\site-packages\\allure_commons\\_allure.py\", line 185, in __call__\n    return self._fixture_function(*args, **kwargs)\n  File \"c:\\basicpythonautomationframework\\venv\\lib\\site-packages\\_pytest\\fixtures.py\", line 926, in _teardown_yield_fixture\n    next(it)\n  File \"C:\\BasicPythonAutomationFramework\\tests\\conftest.py\", line 23, in driver_get\n    driver.close()\n  File \"c:\\basicpythonautomationframework\\venv\\lib\\site-packages\\selenium\\webdriver\\remote\\webdriver.py\", line 688, in close\n    self.execute(Command.CLOSE)\n  File \"c:\\basicpythonautomationframework\\venv\\lib\\site-packages\\selenium\\webdriver\\remote\\webdriver.py\", line 321, in execute\n    self.error_handler.check_response(response)\n  File \"c:\\basicpythonautomationframework\\venv\\lib\\site-packages\\selenium\\webdriver\\remote\\errorhandler.py\", line 242, in check_response\n    raise exception_class(message, screen, stacktrace)\n"}, "start": 1603353711089, "stop": 1603353715174}], "start": 1603353626355, "stop": 1603353715174}