{"uuid": "c4ac3236-f4be-4e1b-96be-949379d0a477", "children": ["6f1c0e22-f120-47c0-9f31-0e61eca8d283", "ed05650b-4df4-4ad6-aa0e-7d4315e5e4cf", "dd654ecb-67aa-4ded-979d-a388079e9d77", "df6d2033-91f5-41ef-aaf5-c57f59ff6964", "f775eeda-6a87-4fbf-a441-5babec828ba6", "6081a965-484d-43a9-b1f7-1b148476bb19", "91387c22-6df9-4093-8d3c-d9e825fe5c8e", "0b2916a9-d739-4364-aa36-119a89e670b4", "8ad5dacd-c3f5-4c6b-ba99-9a2c1caa833c", "b1497736-50e0-4dc4-be8f-9c95c4a791ec", "da844bea-1f46-4342-b286-08a529866ab8"], "befores": [{"name": "driver_get", "status": "passed", "start": 1651404864702, "stop": 1651404869821}], "afters": [{"name": "driver_get::0", "status": "broken", "statusDetails": {"message": "selenium.common.exceptions.WebDriverException: Message: chrome not reachable\n  (Session info: chrome=100.0.4896.127)\n\n", "trace": "  File \"C:\\Python_UI_Automation\\venv\\lib\\site-packages\\allure_commons\\_allure.py\", line 185, in __call__\n    return self._fixture_function(*args, **kwargs)\n  File \"C:\\Python_UI_Automation\\venv\\lib\\site-packages\\_pytest\\fixtures.py\", line 926, in _teardown_yield_fixture\n    next(it)\n  File \"C:\\Python_UI_Automation\\tests\\conftest.py\", line 28, in driver_get\n    driver.close()\n  File \"C:\\Python_UI_Automation\\venv\\lib\\site-packages\\selenium\\webdriver\\remote\\webdriver.py\", line 688, in close\n    self.execute(Command.CLOSE)\n  File \"C:\\Python_UI_Automation\\venv\\lib\\site-packages\\selenium\\webdriver\\remote\\webdriver.py\", line 321, in execute\n    self.error_handler.check_response(response)\n  File \"C:\\Python_UI_Automation\\venv\\lib\\site-packages\\selenium\\webdriver\\remote\\errorhandler.py\", line 242, in check_response\n    raise exception_class(message, screen, stacktrace)\n"}, "start": 1651405074651, "stop": 1651405078721}], "start": 1651404864702, "stop": 1651405078721}